<?xml version="1.0" ?>
<robot name="dreamwalker_dummy" xmlns:xacro="http://www.ros.org/wiki/xacro">

	<link name="support_element">
		
		<inertial>
			<mass value="0.8"/>
			<origin xyz="0 0 0.082" rpy="0 0 0"/>
			<inertia ixx="0.002858" ixy="0" ixz="0" iyy="0.002726" iyz="0" izz="0.0006479"/>
		</inertial>

		<collision name="collision_base">
			<origin xyz="0 0 0.095" rpy="0 0 0"/>
			<geometry>
				<box size="0.06 0.14 0.19"/>
			</geometry>
			<contact_coefficient mu="100.0" mu2="100.0" k_p="1000000.0"  k_d="100.0" />
		</collision>

		<visual>
			<origin xyz="0 0 0" rpy="0 0 0"/>
			<geometry>
				<mesh filename="package://dreamwalker_description/meshes/support_test_element.stl" scale="0.001 0.001 0.001" />
			</geometry>
		</visual>

	</link>


	<!--### BODY ### -->

	<link name="main_body">
		
		<inertial>
			<mass value="0.388"/>
			<origin xyz="0 0 0.0155" rpy="0 0 0"/>
			<inertia ixx="0.001096" ixy="0" ixz="0" iyy="0.0006744" iyz="0" izz="0.001658"/>
		</inertial>

		<collision name="collision_base">
			<origin xyz="0 0 0" rpy="0 0 0"/>
			<geometry>
				<mesh filename="package://dreamwalker_description/meshes/main_body_collision.stl" scale="0.001 0.001 0.001" />
			</geometry>
		</collision>

		<visual>
			<origin xyz="0 0 0" rpy="0 0 0"/>
			<geometry>
				<mesh filename="package://dreamwalker_description/meshes/main_body.stl" scale="0.001 0.001 0.001" />
			</geometry>
			<material name="Cyan">
  		        <color rgba="0 1.0 1.0 1.0"/>
  			</material>
		</visual>

	</link>

	<!--### SHOULDERS ### -->

	<link name="link_shoulder1">
		
		<inertial>
			<mass value="0.0198"/>
			<origin xyz="-0.008165 0.022472 0" rpy="0 0 0"/>
			<inertia ixx="0.000003218011" ixy="0.000000199995" ixz="0" iyy="0.000001946476" iyz="0" izz="0.000004027678"/>
		</inertial>

		<collision name="collision_base">
			<origin xyz="0 0 0" rpy="0 0 0"/>
			<geometry>
				<box size="0.1 0.01 0.01"/>
			</geometry>
		</collision>

		<visual>
			<origin xyz="0 0 0" rpy="0 0 0"/>
			<geometry>
				<mesh filename="package://dreamwalker_description/meshes/link_shoulder1.stl" scale="0.001 0.001 0.001" />
			</geometry>
		</visual>

	</link>


	<link name="link_shoulder2">
		
		<inertial>
			<mass value="0.0198"/>
			<origin xyz="0.008165 0.022472 0" rpy="0 0 0"/>
			<inertia ixx="0.000003218011" ixy="-0.000000199995" ixz="0" iyy="0.000001946476" iyz="0" izz="0.000004027678"/>
		</inertial>

		<collision name="collision_base">
			<origin xyz="0 0 0" rpy="0 0 0"/>
			<geometry>
				<box size="0.01 0.01 0.01"/>
			</geometry>
		</collision>

		<visual>
			<origin xyz="0 0 0" rpy="0 0 0"/>
			<geometry>
				<mesh filename="package://dreamwalker_description/meshes/link_shoulder2.stl" scale="0.001 0.001 0.001" />
			</geometry>
		</visual>

	</link>


	<link name="link_shoulder3">
		
		<inertial>
			<mass value="0.0198"/>
			<origin xyz="-0.008165 -0.022472 0" rpy="0 0 0"/>
			<inertia ixx="0.000003218011" ixy="-0.000000199995" ixz="0" iyy="0.000001946476" iyz="0" izz="0.000004027678"/>
		</inertial>

		<collision name="collision_base">
			<origin xyz="0 0 0" rpy="0 0 0"/>
			<geometry>
				<box size="0.01 0.01 0.01"/>
			</geometry>
		</collision>

		<visual>
			<origin xyz="0 0 0" rpy="0 0 0"/>
			<geometry>
				<mesh filename="package://dreamwalker_description/meshes/link_shoulder3.stl" scale="0.001 0.001 0.001" />
			</geometry>
		</visual>

	</link>


	<link name="link_shoulder4">
		
		<inertial>
			<mass value="0.0198"/>
			<origin xyz="0.008165 -0.022472 0" rpy="0 0 0"/>
			<inertia ixx="0.000003218011" ixy="0.000000199995" ixz="0" iyy="0.000001946476" iyz="0" izz="0.000004027678"/>
		</inertial>

		<collision name="collision_base">
			<origin xyz="0 0 0" rpy="0 0 0"/>
			<geometry>
				<box size="0.01 0.01 0.01"/>
			</geometry>
		</collision>

		<visual>
			<origin xyz="0 0 0" rpy="0 0 0"/>
			<geometry>
				<mesh filename="package://dreamwalker_description/meshes/link_shoulder4.stl" scale="0.001 0.001 0.001" />
			</geometry>
		</visual>

	</link>

	<!--### FEMURS ### -->

	<link name="link_femur1">
		
		<inertial>
			<mass value="0.0218"/>
			<origin xyz="-0.012278 0 -0.031262" rpy="0 0 0"/>
			<inertia ixx="0.00001388" ixy="0" ixz="-0.000000908897" iyy="0.00001369" iyz="0" izz="0.000001695609"/>
		</inertial>

		<collision name="collision_base">
			<origin xyz="0 0 0" rpy="0 0 0"/>
			<geometry>
				<box size="0.01 0.01 0.01"/>
			</geometry>
		</collision>

		<visual>
			<origin xyz="0 0 0" rpy="0 0 0"/>
			<geometry>
				<mesh filename="package://dreamwalker_description/meshes/link_femur1.stl" scale="0.001 0.001 0.001" />
			</geometry>
		</visual>

	</link>


	<link name="link_femur2">
		
		<inertial>
			<mass value="0.0218"/>
			<origin xyz="0.012278 0 -0.031262" rpy="0 0 0"/>
			<inertia ixx="0.00001388" ixy="0" ixz="0.000000908897" iyy="0.00001369" iyz="0" izz="0.000001695609"/>
		</inertial>

		<collision name="collision_base">
			<origin xyz="0 0 0" rpy="0 0 0"/>
			<geometry>
				<box size="0.01 0.01 0.01"/>
			</geometry>
		</collision>

		<visual>
			<origin xyz="0 0 0" rpy="0 0 0"/>
			<geometry>
				<mesh filename="package://dreamwalker_description/meshes/link_femur2.stl" scale="0.001 0.001 0.001" />
			</geometry>
		</visual>

	</link>


	<link name="link_femur3">
		
		<inertial>
			<mass value="0.0218"/>
			<origin xyz="-0.012278 0 -0.031262" rpy="0 0 0"/>
			<inertia ixx="0.00001388" ixy="0" ixz="-0.000000908897" iyy="0.00001369" iyz="0" izz="0.000001695609"/>
		</inertial>

		<collision name="collision_base">
			<origin xyz="0 0 0" rpy="0 0 0"/>
			<geometry>
				<box size="0.01 0.01 0.01"/>
			</geometry>
		</collision>

		<visual>
			<origin xyz="0 0 0" rpy="0 0 0"/>
			<geometry>
				<mesh filename="package://dreamwalker_description/meshes/link_femur3.stl" scale="0.001 0.001 0.001" />
			</geometry>
		</visual>

	</link>


	<link name="link_femur4">
		
		<inertial>
			<mass value="0.0218"/>
			<origin xyz="0.012278 0 -0.031262" rpy="0 0 0"/>
			<inertia ixx="0.00001388" ixy="0" ixz="0.000000908897" iyy="0.00001369" iyz="0" izz="0.000001695609"/>
		</inertial>

		<collision name="collision_base">
			<origin xyz="0 0 0" rpy="0 0 0"/>
			<geometry>
				<box size="0.01 0.01 0.01"/>
			</geometry>
		</collision>

		<visual>
			<origin xyz="0 0 0" rpy="0 0 0"/>
			<geometry>
				<mesh filename="package://dreamwalker_description/meshes/link_femur4.stl" scale="0.001 0.001 0.001" />
			</geometry>
		</visual>

	</link>


	<link name="link_tibia1">
		
		<inertial>
			<mass value="0.00651"/>
			<origin xyz="-0.0025 0.000876 -0.027677" rpy="0 0 0"/>
			<inertia ixx="0.000003593654" ixy="0" ixz="0" iyy="0.000003455444" iyz="0.000000074876" izz="0.000000165334"/>
		</inertial>

		<collision name="collision_base">
			<origin xyz="0 0 0" rpy="0 0 0"/>
			<geometry>
				<box size="0.01 0.01 0.01"/>
			</geometry>
		</collision>

		<visual>
			<origin xyz="0 0 0" rpy="0 0 0"/>
			<geometry>
				<mesh filename="package://dreamwalker_description/meshes/link_tibia1.stl" scale="0.001 0.001 0.001" />
			</geometry>
		</visual>

	</link>


	<link name="link_tibia2">
		
		<inertial>
			<mass value="0.00651"/>
			<origin xyz="0.0025 0.000876 -0.027677" rpy="0 0 0"/>
			<inertia ixx="0.000003593654" ixy="0" ixz="0" iyy="0.000003455444" iyz="0.000000074876" izz="0.000000165334"/>
		</inertial>

		<collision name="collision_base">
			<origin xyz="0 0 0" rpy="0 0 0"/>
			<geometry>
				<box size="0.01 0.01 0.01"/>
			</geometry>
		</collision>

		<visual>
			<origin xyz="0 0 0" rpy="0 0 0"/>
			<geometry>
				<mesh filename="package://dreamwalker_description/meshes/link_tibia2.stl" scale="0.001 0.001 0.001" />
			</geometry>
		</visual>

	</link>


	<link name="link_tibia3">
		
		<inertial>
			<mass value="0.00651"/>
			<origin xyz="-0.0025 -0.000876 -0.027677" rpy="0 0 0"/>
			<inertia ixx="0.000003593654" ixy="0" ixz="0" iyy="0.000003455444" iyz="-0.000000074876" izz="0.000000165334"/>
		</inertial>

		<collision name="collision_base">
			<origin xyz="0 0 0" rpy="0 0 0"/>
			<geometry>
				<box size="0.01 0.01 0.01"/>
			</geometry>
		</collision>

		<visual>
			<origin xyz="0 0 0" rpy="0 0 0"/>
			<geometry>
				<mesh filename="package://dreamwalker_description/meshes/link_tibia3.stl" scale="0.001 0.001 0.001" />
			</geometry>
		</visual>

	</link>


	<link name="link_tibia4">
		
		<inertial>
			<mass value="0.00651"/>
			<origin xyz="0.0025 -0.000876 -0.027677" rpy="0 0 0"/>
			<inertia ixx="0.000003593654" ixy="0" ixz="0" iyy="0.000003455444" iyz="-0.000000074876" izz="0.000000165334"/>
		</inertial>

		<collision name="collision_base">
			<origin xyz="0 0 0" rpy="0 0 0"/>
			<geometry>
				<box size="0.01 0.01 0.01"/>
			</geometry>
		</collision>

		<visual>
			<origin xyz="0 0 0" rpy="0 0 0"/>
			<geometry>
				<mesh filename="package://dreamwalker_description/meshes/link_tibia4.stl" scale="0.001 0.001 0.001" />
			</geometry>
		</visual>

	</link>


	<link name="link_foot1">
		
		<inertial>
			<mass value="0.0013"/>
			<origin xyz="0 0 -0.004355" rpy="0 0 0"/>
			<inertia ixx="0.000000043185" ixy="0" ixz="0" iyy="0.000000029326" iyz="-0.000000074876" izz="0.000000054089"/>
		</inertial>

		<collision name="collision_base">
			<origin xyz="0 0 0" rpy="0 0 0"/>
			<geometry>
				<mesh filename="package://dreamwalker_description/meshes/link_foot.stl" scale="0.001 0.001 0.001" />
			</geometry>
			<contact_coefficient mu="100" mu2="100" k_p="1000000.0"  k_d="100.0" />
		</collision>

		<visual>
			<origin xyz="0 0 0" rpy="0 0 0"/>
			<geometry>
				<mesh filename="package://dreamwalker_description/meshes/link_foot.stl" scale="0.001 0.001 0.001" />
			</geometry>
		</visual>

	</link>


	<link name="link_foot2">
		
		<inertial>
			<mass value="0.0013"/>
			<origin xyz="0 0 -0.004355" rpy="0 0 0"/>
			<inertia ixx="0.000000043185" ixy="0" ixz="0" iyy="0.000000029326" iyz="-0.000000074876" izz="0.000000054089"/>
		</inertial>

		<collision name="collision_base">
			<origin xyz="0 0 0" rpy="0 0 0"/>
			<geometry>
				<mesh filename="package://dreamwalker_description/meshes/link_foot.stl" scale="0.001 0.001 0.001" />
			</geometry>
			<contact_coefficient mu="100" mu2="100" k_p="1000000.0"  k_d="100.0" />
		</collision>

		<visual>
			<origin xyz="0 0 0" rpy="0 0 0"/>
			<geometry>
				<mesh filename="package://dreamwalker_description/meshes/link_foot.stl" scale="0.001 0.001 0.001" />
			</geometry>
		</visual>

	</link>


	<link name="link_foot3">
		
		<inertial>
			<mass value="0.0013"/>
			<origin xyz="0 0 -0.004355" rpy="0 0 0"/>
			<inertia ixx="0.000000043185" ixy="0" ixz="0" iyy="0.000000029326" iyz="-0.000000074876" izz="0.000000054089"/>
		</inertial>

		<collision name="collision_base">
			<origin xyz="0 0 0" rpy="0 0 0"/>
			<geometry>
				<mesh filename="package://dreamwalker_description/meshes/link_foot.stl" scale="0.001 0.001 0.001" />
			</geometry>
			<contact_coefficient mu="100" mu2="100" k_p="1000000.0"  k_d="100.0" />
		</collision>

		<visual>
			<origin xyz="0 0 0" rpy="0 0 0"/>
			<geometry>
				<mesh filename="package://dreamwalker_description/meshes/link_foot.stl" scale="0.001 0.001 0.001" />
			</geometry>
		</visual>

	</link>


	<link name="link_foot4">
		
		<inertial>
			<mass value="0.0013"/>
			<origin xyz="0 0 -0.004355" rpy="0 0 0"/>
			<inertia ixx="0.000000043185" ixy="0" ixz="0" iyy="0.000000029326" iyz="-0.000000074876" izz="0.000000054089"/>
		</inertial>

		<collision name="collision_base">
			<origin xyz="0 0 0" rpy="0 0 0"/>
			<geometry>
				<mesh filename="package://dreamwalker_description/meshes/link_foot.stl" scale="0.001 0.001 0.001" />
			</geometry>
			<contact_coefficient mu="100" mu2="100" k_p="1000000.0"  k_d="100.0" />
		</collision>

		<visual>
			<origin xyz="0 0 0" rpy="0 0 0"/>
			<geometry>
				<mesh filename="package://dreamwalker_description/meshes/link_foot.stl" scale="0.001 0.001 0.001" />
			</geometry>
		</visual>

	</link>


	<!-- ### JOINTS ### -->

	<joint name="dummy_joint" type="fixed">
		
		<origin xyz="0 0 0.19" rpy="0 0 0"/>
		<parent link="support_element"/>
		<child link="main_body"/>
	</joint>


	<joint name="shoulder_joint1" type="revolute">
		
		<origin xyz="-0.062 0.064 0.022" rpy="0 0 0"/>
		<axis xyz="0 1 0"/>
		<parent link="main_body"/>
		<child link="link_shoulder1"/>
		<limit effort="30" velocity="5.0" lower="-0.5235987755983" upper="0.5235987755983" />
		<dynamics damping="0.7" friction="0.1"/>
	</joint>

	<joint name="shoulder_joint2" type="revolute">
		
		<origin xyz="0.062 0.064 0.022" rpy="0 0 0"/>
		<axis xyz="0 1 0"/>
		<parent link="main_body"/>
		<child link="link_shoulder2"/>
		<limit effort="30" velocity="5.0" lower="-0.5235987755983" upper="0.5235987755983" />
		<dynamics damping="0.0" friction="1.0"/>
	</joint>

	<joint name="shoulder_joint3" type="revolute">
		
		<origin xyz="-0.062 -0.064 0.022" rpy="0 0 0"/>
		<axis xyz="0 1 0"/>
		<parent link="main_body"/>
		<child link="link_shoulder3"/>
		<limit effort="30" velocity="5.0" lower="-0.5235987755983" upper="0.5235987755983" />
		<dynamics damping="0.0" friction="1.0"/>
	</joint>

	<joint name="shoulder_joint4" type="revolute">
		
		<origin xyz="0.062 -0.064 0.022" rpy="0 0 0"/>
		<axis xyz="0 1 0"/>
		<parent link="main_body"/>
		<child link="link_shoulder4"/>
		<limit effort="30" velocity="1.0" lower="-0.52359" upper="0.52359" />
		<dynamics damping="0.0" friction="1.0"/>
	</joint>

	<joint name="limb_joint1" type="revolute">
		
		<origin xyz="-0.024 0.0305 0" rpy="0 0 0"/>
		<axis xyz="1 0 0"/>
		<parent link="link_shoulder1"/>
		<child link="link_femur1"/>
		<limit effort="30" velocity="1.0" lower="-1.57079" upper="1.57079" />
		<dynamics damping="0.0" friction="1.0"/>
	</joint>

	<joint name="limb_joint2" type="revolute">
		
		<origin xyz="0.024 0.0305 0" rpy="0 0 0"/>
		<axis xyz="1 0 0"/>
		<parent link="link_shoulder2"/>
		<child link="link_femur2"/>
		<limit effort="30" velocity="1.0" lower="-1.57079" upper="1.57079" />
		<dynamics damping="0.0" friction="1.0"/>
	</joint>

	<joint name="limb_joint3" type="revolute">
		
		<origin xyz="-0.024 -0.0305 0" rpy="0 0 0"/>
		<axis xyz="1 0 0"/>
		<parent link="link_shoulder3"/>
		<child link="link_femur3"/>
		<limit effort="30" velocity="1.0" lower="-1.57079" upper="1.57079" />
		<dynamics damping="0.0" friction="1.0"/>
	</joint>

	<joint name="limb_joint4" type="revolute">
		
		<origin xyz="0.024 -0.0305 0" rpy="0 0 0"/>
		<axis xyz="1 0 0"/>
		<parent link="link_shoulder4"/>
		<child link="link_femur4"/>
		<limit effort="30" velocity="1.0" lower="-1.57079" upper="1.57079" />
		<dynamics damping="0.0" friction="1.0"/>
	</joint>

	<joint name="knee_joint1" type="revolute">
		
		<origin xyz="0.005 0 -0.055" rpy="0 0 0"/>
		<axis xyz="1 0 0"/>
		<parent link="link_femur1"/>
		<child link="link_tibia1"/>
		<limit effort="30" velocity="1.0" lower="0" upper="2.09439" />
		<dynamics damping="0.0" friction="1.0"/>
	</joint>

	<joint name="knee_joint2" type="revolute">
		
		<origin xyz="-0.005 0 -0.055" rpy="0 0 0"/>
		<axis xyz="1 0 0"/>
		<parent link="link_femur2"/>
		<child link="link_tibia2"/>
		<limit effort="30" velocity="1.0" lower="0" upper="2.09439" />
		<dynamics damping="0.0" friction="1.0"/>
	</joint>

	<joint name="knee_joint3" type="revolute">
		
		<origin xyz="0.005 0 -0.055" rpy="0 0 0"/>
		<axis xyz="1 0 0"/>
		<parent link="link_femur3"/>
		<child link="link_tibia3"/>
		<limit effort="30" velocity="1.0" lower="-2.09439" upper="0" />
		<dynamics damping="0.0" friction="1.0"/>
	</joint>

	<joint name="knee_joint4" type="revolute">
		
		<origin xyz="-0.005 0 -0.055" rpy="0 0 0"/>
		<axis xyz="1 0 0"/>
		<parent link="link_femur4"/>
		<child link="link_tibia4"/>
		<limit effort="30" velocity="1.0" lower="-2.09439" upper="0" />
		<dynamics damping="0.0" friction="1.0"/>
	</joint>

	<joint name="foot_joint1" type="fixed">
		
		<origin xyz="-0.0025 0 -0.065" rpy="-0.5235987755983 0 0"/>
		<parent link="link_tibia1"/>
		<child link="link_foot1"/>
	</joint>

	<joint name="foot_joint2" type="fixed">
		
		<origin xyz="0.0025 0 -0.065" rpy="-0.5235987755983 0 0"/>
		<parent link="link_tibia2"/>
		<child link="link_foot2"/>
	</joint>


	<joint name="foot_joint3" type="fixed">
		
		<origin xyz="-0.0025 0 -0.065" rpy="0.5235987755983 0 0"/>
		<parent link="link_tibia3"/>
		<child link="link_foot3"/>
	</joint>


	<joint name="foot_joint4" type="fixed">
		
		<origin xyz="0.0025 0 -0.065" rpy="0.5235987755983 0 0"/>
		<parent link="link_tibia4"/>
		<child link="link_foot4"/>
	</joint>

	<!-- ### GAZEBO ### -->
	<!--
	<gazebo>
  		<plugin name="gazebo_ros_control" filename="libgazebo_ros_control.so">
    		<robotNamespace>/roboter</robotNamespace>
  		</plugin>
	</gazebo>
										-->
	<!-- ### TRANSMISSIONS -->

	<gazebo reference="main_body">
    	<material>Gazebo/Grey</material>
  	</gazebo>

  	<gazebo reference="link_foot1">
    	<material>Gazebo/Black</material>
  	</gazebo>

  	<gazebo reference="link_foot2">
    	<material>Gazebo/Black</material>
  	</gazebo>

  	<gazebo reference="link_foot3">
    	<material>Gazebo/Black</material>
  	</gazebo>

  	<gazebo reference="link_foot4">
    	<material>Gazebo/Black</material>
  	</gazebo>

</robot>
