<?xml version="1.0" ?>
<robot name="dreamwalker" xmlns:xacro="http://www.ros.org/wiki/xacro">

	
	<!--### BODY ### -->

	<link name="main_body">
		
		<inertial>
			<mass value="0.388"/>
			<origin xyz="0 0 0.0155" rpy="0 0 0"/>
			<inertia ixx="0.001096" ixy="0" ixz="0" iyy="0.0006744" iyz="0" izz="0.001658"/>
		</inertial>

		<collision name="collision_base">
			<origin xyz="0 0 0" rpy="0 0 0"/>
			<geometry>
				<mesh filename="package://dreamwalker_description/meshes/main_body_collision.stl" scale="0.001 0.001 0.001" />
			</geometry>
		</collision>

		<visual>
			<origin xyz="0 0 0" rpy="0 0 0"/>
			<geometry>
				<mesh filename="package://dreamwalker_description/meshes/main_body.stl" scale="0.001 0.001 0.001" />
			</geometry>
		</visual>

	</link>

	<!--### SHOULDERS ### -->

	<link name="link_shoulder1">
		
		<inertial>
			<mass value="0.0198"/>
			<origin xyz="-0.008165 0.022472 0" rpy="0 0 0"/>
			<inertia ixx="0.000003218011" ixy="0.000000199995" ixz="0" iyy="0.000001946476" iyz="0" izz="0.000004027678"/>
		</inertial>

		<collision name="collision_base">
			<origin xyz="0 0 0" rpy="0 0 0"/>
			<geometry>
				<mesh filename="package://dreamwalker_description/meshes/link_shoulder1.stl" scale="0.001 0.001 0.001" />
			</geometry>
		</collision>

		<visual>
			<origin xyz="0 0 0" rpy="0 0 0"/>
			<geometry>
				<mesh filename="package://dreamwalker_description/meshes/link_shoulder1.stl" scale="0.001 0.001 0.001" />
			</geometry>
		</visual>

	</link>


	<link name="link_shoulder2">
		
		<inertial>
			<mass value="0.0198"/>
			<origin xyz="0.008165 0.022472 0" rpy="0 0 0"/>
			<inertia ixx="0.000003218011" ixy="-0.000000199995" ixz="0" iyy="0.000001946476" iyz="0" izz="0.000004027678"/>
		</inertial>

		<collision name="collision_base">
			<origin xyz="0 0 0" rpy="0 0 0"/>
			<geometry>
				<mesh filename="package://dreamwalker_description/meshes/link_shoulder2.stl" scale="0.001 0.001 0.001" />
			</geometry>
		</collision>

		<visual>
			<origin xyz="0 0 0" rpy="0 0 0"/>
			<geometry>
				<mesh filename="package://dreamwalker_description/meshes/link_shoulder2.stl" scale="0.001 0.001 0.001" />
			</geometry>
		</visual>

	</link>


	<link name="link_shoulder3">
		
		<inertial>
			<mass value="0.0198"/>
			<origin xyz="-0.008165 -0.022472 0" rpy="0 0 0"/>
			<inertia ixx="0.000003218011" ixy="-0.000000199995" ixz="0" iyy="0.000001946476" iyz="0" izz="0.000004027678"/>
		</inertial>

		<collision name="collision_base">
			<origin xyz="0 0 0" rpy="0 0 0"/>
			<geometry>
				<mesh filename="package://dreamwalker_description/meshes/link_shoulder3.stl" scale="0.001 0.001 0.001" />
			</geometry>
		</collision>

		<visual>
			<origin xyz="0 0 0" rpy="0 0 0"/>
			<geometry>
				<mesh filename="package://dreamwalker_description/meshes/link_shoulder3.stl" scale="0.001 0.001 0.001" />
			</geometry>
		</visual>

	</link>


	<link name="link_shoulder4">
		
		<inertial>
			<mass value="0.0198"/>
			<origin xyz="0.008165 -0.022472 0" rpy="0 0 0"/>
			<inertia ixx="0.000003218011" ixy="0.000000199995" ixz="0" iyy="0.000001946476" iyz="0" izz="0.000004027678"/>
		</inertial>

		<collision name="collision_base">
			<origin xyz="0 0 0" rpy="0 0 0"/>
			<geometry>
				<mesh filename="package://dreamwalker_description/meshes/link_shoulder4.stl" scale="0.001 0.001 0.001" />
			</geometry>
		</collision>

		<visual>
			<origin xyz="0 0 0" rpy="0 0 0"/>
			<geometry>
				<mesh filename="package://dreamwalker_description/meshes/link_shoulder4.stl" scale="0.001 0.001 0.001" />
			</geometry>
		</visual>

	</link>

	<!--### FEMURS ### -->

	<link name="link_femur1">
		
		<inertial>
			<mass value="0.0218"/>
			<origin xyz="-0.012278 0 -0.031262" rpy="0 0 0"/>
			<inertia ixx="0.00001388" ixy="0" ixz="-0.000000908897" iyy="0.00001369" iyz="0" izz="0.000001695609"/>
		</inertial>

		<collision name="collision_base">
			<origin xyz="0 0 0" rpy="0 0 0"/>
			<geometry>
				<mesh filename="package://dreamwalker_description/meshes/link_femur1.stl" scale="0.001 0.001 0.001" />
			</geometry>
		</collision>

		<visual>
			<origin xyz="0 0 0" rpy="0 0 0"/>
			<geometry>
				<mesh filename="package://dreamwalker_description/meshes/link_femur1.stl" scale="0.001 0.001 0.001" />
			</geometry>
		</visual>

	</link>


	<link name="link_femur2">
		
		<inertial>
			<mass value="0.0218"/>
			<origin xyz="0.012278 0 -0.031262" rpy="0 0 0"/>
			<inertia ixx="0.00001388" ixy="0" ixz="0.000000908897" iyy="0.00001369" iyz="0" izz="0.000001695609"/>
		</inertial>

		<collision name="collision_base">
			<origin xyz="0 0 0" rpy="0 0 0"/>
			<geometry>
				<mesh filename="package://dreamwalker_description/meshes/link_femur2.stl" scale="0.001 0.001 0.001" />
			</geometry>
		</collision>

		<visual>
			<origin xyz="0 0 0" rpy="0 0 0"/>
			<geometry>
				<mesh filename="package://dreamwalker_description/meshes/link_femur2.stl" scale="0.001 0.001 0.001" />
			</geometry>
		</visual>

	</link>


	<link name="link_femur3">
		
		<inertial>
			<mass value="0.0218"/>
			<origin xyz="-0.012278 0 -0.031262" rpy="0 0 0"/>
			<inertia ixx="0.00001388" ixy="0" ixz="-0.000000908897" iyy="0.00001369" iyz="0" izz="0.000001695609"/>
		</inertial>

		<collision name="collision_base">
			<origin xyz="0 0 0" rpy="0 0 0"/>
			<geometry>
				<mesh filename="package://dreamwalker_description/meshes/link_femur3.stl" scale="0.001 0.001 0.001" />
			</geometry>
		</collision>

		<visual>
			<origin xyz="0 0 0" rpy="0 0 0"/>
			<geometry>
				<mesh filename="package://dreamwalker_description/meshes/link_femur3.stl" scale="0.001 0.001 0.001" />
			</geometry>
		</visual>

	</link>


	<link name="link_femur4">
		
		<inertial>
			<mass value="0.0218"/>
			<origin xyz="0.012278 0 -0.031262" rpy="0 0 0"/>
			<inertia ixx="0.00001388" ixy="0" ixz="0.000000908897" iyy="0.00001369" iyz="0" izz="0.000001695609"/>
		</inertial>

		<collision name="collision_base">
			<origin xyz="0 0 0" rpy="0 0 0"/>
			<geometry>
				<mesh filename="package://dreamwalker_description/meshes/link_femur4.stl" scale="0.001 0.001 0.001" />
			</geometry>
		</collision>

		<visual>
			<origin xyz="0 0 0" rpy="0 0 0"/>
			<geometry>
				<mesh filename="package://dreamwalker_description/meshes/link_femur4.stl" scale="0.001 0.001 0.001" />
			</geometry>
		</visual>

	</link>


	<link name="link_tibia1">
		
		<inertial>
			<mass value="0.00651"/>
			<origin xyz="-0.0025 0.000876 -0.027677" rpy="0 0 0"/>
			<inertia ixx="0.000003593654" ixy="0" ixz="0" iyy="0.000003455444" iyz="0.000000074876" izz="0.000000165334"/>
		</inertial>

		<collision name="collision_base">
			<origin xyz="0 0 0" rpy="0 0 0"/>
			<geometry>
				<mesh filename="package://dreamwalker_description/meshes/link_tibia1.stl" scale="0.001 0.001 0.001" />
			</geometry>
		</collision>

		<visual>
			<origin xyz="0 0 0" rpy="0 0 0"/>
			<geometry>
				<mesh filename="package://dreamwalker_description/meshes/link_tibia1.stl" scale="0.001 0.001 0.001" />
			</geometry>
		</visual>

	</link>


	<link name="link_tibia2">
		
		<inertial>
			<mass value="0.00651"/>
			<origin xyz="0.0025 0.000876 -0.027677" rpy="0 0 0"/>
			<inertia ixx="0.000003593654" ixy="0" ixz="0" iyy="0.000003455444" iyz="0.000000074876" izz="0.000000165334"/>
		</inertial>

		<collision name="collision_base">
			<origin xyz="0 0 0" rpy="0 0 0"/>
			<geometry>
				<mesh filename="package://dreamwalker_description/meshes/link_tibia2.stl" scale="0.001 0.001 0.001" />
			</geometry>
		</collision>

		<visual>
			<origin xyz="0 0 0" rpy="0 0 0"/>
			<geometry>
				<mesh filename="package://dreamwalker_description/meshes/link_tibia2.stl" scale="0.001 0.001 0.001" />
			</geometry>
		</visual>

	</link>


	<link name="link_tibia3">
		
		<inertial>
			<mass value="0.00651"/>
			<origin xyz="-0.0025 -0.000876 -0.027677" rpy="0 0 0"/>
			<inertia ixx="0.000003593654" ixy="0" ixz="0" iyy="0.000003455444" iyz="-0.000000074876" izz="0.000000165334"/>
		</inertial>

		<collision name="collision_base">
			<origin xyz="0 0 0" rpy="0 0 0"/>
			<geometry>
				<mesh filename="package://dreamwalker_description/meshes/link_tibia3.stl" scale="0.001 0.001 0.001" />
			</geometry>
		</collision>

		<visual>
			<origin xyz="0 0 0" rpy="0 0 0"/>
			<geometry>
				<mesh filename="package://dreamwalker_description/meshes/link_tibia3.stl" scale="0.001 0.001 0.001" />
			</geometry>
		</visual>

	</link>


	<link name="link_tibia4">
		
		<inertial>
			<mass value="0.00651"/>
			<origin xyz="0.0025 -0.000876 -0.027677" rpy="0 0 0"/>
			<inertia ixx="0.000003593654" ixy="0" ixz="0" iyy="0.000003455444" iyz="-0.000000074876" izz="0.000000165334"/>
		</inertial>

		<collision name="collision_base">
			<origin xyz="0 0 0" rpy="0 0 0"/>
			<geometry>
				<mesh filename="package://dreamwalker_description/meshes/link_tibia4.stl" scale="0.001 0.001 0.001" />
			</geometry>
		</collision>

		<visual>
			<origin xyz="0 0 0" rpy="0 0 0"/>
			<geometry>
				<mesh filename="package://dreamwalker_description/meshes/link_tibia4.stl" scale="0.001 0.001 0.001" />
			</geometry>
		</visual>

	</link>


	<!-- ### JOINTS ### -->

	<joint name="shoulder_joint1" type="continuous">
		
		<origin xyz="-0.062 0.064 0.022" rpy="0 0 0"/>
		<axis xyz="0 1 0"/>
		<parent link="main_body"/>
		<child link="link_shoulder1"/>
		<!--<limit effort="30" velocity="1.0" lower="-1.57079" upper="1.57079" />
		<dynamics damping="0.0" friction="1.0"/> -->
	</joint>

	<joint name="shoulder_joint2" type="continuous">
		
		<origin xyz="0.062 0.064 0.022" rpy="0 0 0"/>
		<axis xyz="0 1 0"/>
		<parent link="main_body"/>
		<child link="link_shoulder2"/>
		<!-- <limit effort="30" velocity="1.0" lower="-1.57079" upper="1.57079" />
		<dynamics damping="0.0" friction="1.0"/> -->
	</joint>

	<joint name="shoulder_joint3" type="continuous">
		
		<origin xyz="-0.062 -0.064 0.022" rpy="0 0 0"/>
		<axis xyz="0 1 0"/>
		<parent link="main_body"/>
		<child link="link_shoulder3"/>
		<!--<limit effort="30" velocity="1.0" lower="-1.57079" upper="1.57079" />
		<dynamics damping="0.0" friction="1.0"/> -->
	</joint>

	<joint name="shoulder_joint4" type="continuous">
		
		<origin xyz="0.062 -0.064 0.022" rpy="0 0 0"/>
		<axis xyz="0 1 0"/>
		<parent link="main_body"/>
		<child link="link_shoulder4"/>
		<!-- <limit effort="30" velocity="1.0" lower="-1.57079" upper="1.57079" />
		<dynamics damping="0.0" friction="1.0"/> -->
	</joint>

	<joint name="limb_joint1" type="continuous">
		
		<origin xyz="-0.024 0.0305 0" rpy="0 0 0"/>
		<axis xyz="1 0 0"/>
		<parent link="link_shoulder1"/>
		<child link="link_femur1"/>
		<!-- <limit effort="30" velocity="1.0" lower="-1.57079" upper="1.57079" />
		<dynamics damping="0.0" friction="1.0"/> -->
	</joint>

	<joint name="limb_joint2" type="continuous">
		
		<origin xyz="0.024 0.0305 0" rpy="0 0 0"/>
		<axis xyz="1 0 0"/>
		<parent link="link_shoulder2"/>
		<child link="link_femur2"/>
		<!-- <limit effort="30" velocity="1.0" lower="-1.57079" upper="1.57079" />
		<dynamics damping="0.0" friction="1.0"/> -->
	</joint>

	<joint name="limb_joint3" type="continuous">
		
		<origin xyz="-0.024 -0.0305 0" rpy="0 0 0"/>
		<axis xyz="1 0 0"/>
		<parent link="link_shoulder3"/>
		<child link="link_femur3"/>
		<!-- <limit effort="30" velocity="1.0" lower="-1.57079" upper="1.57079" />
		<dynamics damping="0.0" friction="1.0"/> -->
	</joint>

	<joint name="limb_joint4" type="continuous">
		
		<origin xyz="0.024 -0.0305 0" rpy="0 0 0"/>
		<axis xyz="1 0 0"/>
		<parent link="link_shoulder4"/>
		<child link="link_femur4"/>
		<!-- <limit effort="30" velocity="1.0" lower="-1.57079" upper="1.57079" />
		<dynamics damping="0.0" friction="1.0"/> -->
	</joint>

	<joint name="knee_joint1" type="continuous">
		
		<origin xyz="0.005 0 -0.055" rpy="0 0 0"/>
		<axis xyz="1 0 0"/>
		<parent link="link_femur1"/>
		<child link="link_tibia1"/>
		<!-- <limit effort="30" velocity="1.0" lower="-1.57079" upper="1.57079" />
		<dynamics damping="0.0" friction="1.0"/> -->
	</joint>

	<joint name="knee_joint2" type="continuous">
		
		<origin xyz="-0.005 0 -0.055" rpy="0 0 0"/>
		<axis xyz="1 0 0"/>
		<parent link="link_femur2"/>
		<child link="link_tibia2"/>
		<!-- <limit effort="30" velocity="1.0" lower="-1.57079" upper="1.57079" />
		<dynamics damping="0.0" friction="1.0"/> -->
	</joint>

	<joint name="knee_joint3" type="continuous">
		
		<origin xyz="0.005 0 -0.055" rpy="0 0 0"/>
		<axis xyz="1 0 0"/>
		<parent link="link_femur3"/>
		<child link="link_tibia3"/>
		<!-- <limit effort="30" velocity="1.0" lower="-1.57079" upper="1.57079" />
		<dynamics damping="0.0" friction="1.0"/> -->
	</joint>

	<joint name="knee_joint4" type="continuous">
		
		<origin xyz="-0.005 0 -0.055" rpy="0 0 0"/>
		<axis xyz="1 0 0"/>
		<parent link="link_femur4"/>
		<child link="link_tibia4"/>
		<!-- <limit effort="30" velocity="1.0" lower="-1.57079" upper="1.57079" />
		<dynamics damping="0.0" friction="1.0"/> -->
	</joint>

	<!-- ### GAZEBO ### -->
	<!--
	<gazebo>
  		<plugin name="gazebo_ros_control" filename="libgazebo_ros_control.so">
    		<robotNamespace>/roboter</robotNamespace>
  		</plugin>
	</gazebo>
										-->
	<!-- ### TRANSMISSIONS -->

</robot>
